2025-06-12 14:34:18,450 - INFO - Data loaded successfully. X shape: (400, 38448), y shape: (400,)
2025-06-12 14:34:18,488 - INFO - Data split into training/CV (320 rows) and hold-out (80 rows) sets.
2025-06-12 14:34:19,354 - ERROR - [Orchestrator] Error from autogluon_wrapper child process:
Traceback (most recent call last):
  File "/home/nate/Desktop/AutoML/orchestrator.py", line 471, in _runner
    fitted_model = wrapper_instance.fit(X_obj, y_obj)
                   ^^^^^^^^^^^^^^^^^^^^^^^^^^^^^^^^^^
  File "/home/nate/Desktop/AutoML/engines/autogluon_wrapper.py", line 165, in fit
    ag_predictor = TabularPredictor(
                   ^^^^^^^^^^^^^^^^^
  File "/home/nate/.pyenv/versions/3.11.13/lib/python3.11/site-packages/autogluon/tabular/predictor/predictor.py", line 203, in __init__
    self._validate_init_kwargs(kwargs)
  File "/home/nate/.pyenv/versions/3.11.13/lib/python3.11/site-packages/autogluon/tabular/predictor/predictor.py", line 5017, in _validate_init_kwargs
    raise ValueError(f"Invalid kwargs passed: {invalid_keys}\nValid kwargs: {list(valid_kwargs)}")
ValueError: Invalid kwargs passed: ['random_seed']
Valid kwargs: ['learner_kwargs', 'quantile_levels', 'learner_type']

2025-06-12 14:34:19,551 - ERROR - All AutoML engines failed in concurrent run.
2025-06-12 14:34:19,551 - ERROR - An error occurred during meta-search or evaluation: All AutoML engines failed in concurrent run.
Traceback (most recent call last):
  File "/home/nate/Desktop/AutoML/orchestrator.py", line 761, in _cli
    champion_model, fitted_engines, per_engine_metrics = _meta_search_concurrent(
                                                         ^^^^^^^^^^^^^^^^^^^^^^^^
  File "/home/nate/Desktop/AutoML/orchestrator.py", line 589, in _meta_search_concurrent
    raise RuntimeError("All AutoML engines failed in concurrent run.")
RuntimeError: All AutoML engines failed in concurrent run.
