2025-06-12 14:23:52,839 - ERROR - Failed to load data: Predictors file not found: DataSets/3/predictors.csv
Traceback (most recent call last):
  File "/home/nate/Desktop/AutoML/orchestrator.py", line 736, in _cli
    X, y = load_data(args.data, args.target)
           ^^^^^^^^^^^^^^^^^^^^^^^^^^^^^^^^^
  File "/home/nate/Desktop/AutoML/scripts/data_loader.py", line 43, in load_data
    raise FileNotFoundError(f"Predictors file not found: {predictors_path}")
FileNotFoundError: Predictors file not found: DataSets/3/predictors.csv
2025-06-12 14:24:35,824 - INFO - 'DataSets/3' is not an exact file. Attempting to load from directory: DataSets
2025-06-12 14:24:35,825 - INFO - 'DataSets/3' is not an exact file. Attempting to load from directory: DataSets
2025-06-12 14:24:35,825 - ERROR - Failed to load data: Expected exactly one predictors file in DataSets, found 0. Please specify the exact file path or ensure a unique predictor file.
Traceback (most recent call last):
  File "/home/nate/Desktop/AutoML/orchestrator.py", line 749, in _cli
    X, y = load_data(args.data, args.target)
           ^^^^^^^^^^^^^^^^^^^^^^^^^^^^^^^^^
  File "/home/nate/Desktop/AutoML/scripts/data_loader.py", line 45, in load_data
    raise FileNotFoundError(f"Expected exactly one predictors file in {predictors_path}, found {len(predictor_files)}. Please specify the exact file path or ensure a unique predictor file.")
FileNotFoundError: Expected exactly one predictors file in DataSets, found 0. Please specify the exact file path or ensure a unique predictor file.
2025-06-12 14:25:02,669 - ERROR - Failed to load data: Expected exactly one predictors file in DataSets/3, found 0. Please specify the exact file path or ensure a unique predictor file.
Traceback (most recent call last):
  File "/home/nate/Desktop/AutoML/orchestrator.py", line 738, in _cli
    X, y = load_data(args.data, args.target)
           ^^^^^^^^^^^^^^^^^^^^^^^^^^^^^^^^^
  File "/home/nate/Desktop/AutoML/scripts/data_loader.py", line 45, in load_data
    raise FileNotFoundError(f"Expected exactly one predictors file in {predictors_path}, found {len(predictor_files)}. Please specify the exact file path or ensure a unique predictor file.")
FileNotFoundError: Expected exactly one predictors file in DataSets/3, found 0. Please specify the exact file path or ensure a unique predictor file.
2025-06-12 14:25:33,584 - ERROR - Failed to load data: Expected exactly one targets file in DataSets/3, found 0. Please specify the exact file path or ensure a unique target file.
Traceback (most recent call last):
  File "/home/nate/Desktop/AutoML/orchestrator.py", line 738, in _cli
    X, y = load_data(args.data, args.target)
           ^^^^^^^^^^^^^^^^^^^^^^^^^^^^^^^^^
  File "/home/nate/Desktop/AutoML/scripts/data_loader.py", line 55, in load_data
    raise FileNotFoundError(f"Expected exactly one targets file in {target_path}, found {len(target_files)}. Please specify the exact file path or ensure a unique target file.")
FileNotFoundError: Expected exactly one targets file in DataSets/3, found 0. Please specify the exact file path or ensure a unique target file.
2025-06-12 14:25:43,193 - ERROR - Failed to load data: Expected exactly one targets file in DataSets/3, found 0. Please specify the exact file path or ensure a unique target file.
Traceback (most recent call last):
  File "/home/nate/Desktop/AutoML/orchestrator.py", line 738, in _cli
    X, y = load_data(args.data, args.target)
           ^^^^^^^^^^^^^^^^^^^^^^^^^^^^^^^^^
  File "/home/nate/Desktop/AutoML/scripts/data_loader.py", line 55, in load_data
    raise FileNotFoundError(f"Expected exactly one targets file in {target_path}, found {len(target_files)}. Please specify the exact file path or ensure a unique target file.")
FileNotFoundError: Expected exactly one targets file in DataSets/3, found 0. Please specify the exact file path or ensure a unique target file.
2025-06-12 14:27:57,798 - INFO - Data loaded successfully. X shape: (400, 38448), y shape: (400,)
2025-06-12 14:27:57,846 - INFO - Data split into training/CV (320 rows) and hold-out (80 rows) sets.
2025-06-12 14:27:57,850 - ERROR - An error occurred during meta-search or evaluation: Can't pickle local object '_meta_search_concurrent.<locals>._runner'
Traceback (most recent call last):
  File "/home/nate/Desktop/AutoML/orchestrator.py", line 754, in _cli
    champion_model, fitted_engines, per_engine_metrics = _meta_search_concurrent(
                                                         ^^^^^^^^^^^^^^^^^^^^^^^^
  File "/home/nate/Desktop/AutoML/orchestrator.py", line 560, in _meta_search_concurrent
    worker.start()
  File "/home/nate/.pyenv/versions/3.11.13/lib/python3.11/multiprocessing/process.py", line 121, in start
    self._popen = self._Popen(self)
                  ^^^^^^^^^^^^^^^^^
  File "/home/nate/.pyenv/versions/3.11.13/lib/python3.11/multiprocessing/context.py", line 288, in _Popen
    return Popen(process_obj)
           ^^^^^^^^^^^^^^^^^^
  File "/home/nate/.pyenv/versions/3.11.13/lib/python3.11/multiprocessing/popen_spawn_posix.py", line 32, in __init__
    super().__init__(process_obj)
  File "/home/nate/.pyenv/versions/3.11.13/lib/python3.11/multiprocessing/popen_fork.py", line 19, in __init__
    self._launch(process_obj)
  File "/home/nate/.pyenv/versions/3.11.13/lib/python3.11/multiprocessing/popen_spawn_posix.py", line 47, in _launch
    reduction.dump(process_obj, fp)
  File "/home/nate/.pyenv/versions/3.11.13/lib/python3.11/multiprocessing/reduction.py", line 60, in dump
    ForkingPickler(file, protocol).dump(obj)
AttributeError: Can't pickle local object '_meta_search_concurrent.<locals>._runner'
2025-06-12 14:28:25,924 - INFO - Data loaded successfully. X shape: (400, 38448), y shape: (400,)
2025-06-12 14:28:25,961 - INFO - Data split into training/CV (320 rows) and hold-out (80 rows) sets.
2025-06-12 14:28:25,993 - ERROR - An error occurred during meta-search or evaluation: cannot pickle 'module' object
Traceback (most recent call last):
  File "/home/nate/Desktop/AutoML/orchestrator.py", line 754, in _cli
    champion_model, fitted_engines, per_engine_metrics = _meta_search_concurrent(
                                                         ^^^^^^^^^^^^^^^^^^^^^^^^
  File "/home/nate/Desktop/AutoML/orchestrator.py", line 560, in _meta_search_concurrent
    worker.start()
  File "/home/nate/.pyenv/versions/3.11.13/lib/python3.11/multiprocessing/process.py", line 121, in start
    self._popen = self._Popen(self)
                  ^^^^^^^^^^^^^^^^^
  File "/home/nate/.pyenv/versions/3.11.13/lib/python3.11/multiprocessing/context.py", line 288, in _Popen
    return Popen(process_obj)
           ^^^^^^^^^^^^^^^^^^
  File "/home/nate/.pyenv/versions/3.11.13/lib/python3.11/multiprocessing/popen_spawn_posix.py", line 32, in __init__
    super().__init__(process_obj)
  File "/home/nate/.pyenv/versions/3.11.13/lib/python3.11/multiprocessing/popen_fork.py", line 19, in __init__
    self._launch(process_obj)
  File "/home/nate/.pyenv/versions/3.11.13/lib/python3.11/multiprocessing/popen_spawn_posix.py", line 47, in _launch
    reduction.dump(process_obj, fp)
  File "/home/nate/.pyenv/versions/3.11.13/lib/python3.11/multiprocessing/reduction.py", line 60, in dump
    ForkingPickler(file, protocol).dump(obj)
TypeError: cannot pickle 'module' object
2025-06-12 14:29:54,223 - INFO - Data loaded successfully. X shape: (400, 38448), y shape: (400,)
2025-06-12 14:29:54,259 - INFO - Data split into training/CV (320 rows) and hold-out (80 rows) sets.
2025-06-12 14:29:54,978 - INFO - [Orchestrator|autogluon_wrapper] Child process started.
2025-06-12 14:29:54,979 - ERROR - [Orchestrator|autogluon_wrapper] Engine crashed: name 'DEFAULT_METRIC' is not defined
Traceback (most recent call last):
  File "/home/nate/Desktop/AutoML/orchestrator.py", line 470, in _runner
    wrapper_instance = wrapper_class(seed=RANDOM_STATE, timeout_sec=t_sec, run_dir=r_dir)
                       ^^^^^^^^^^^^^^^^^^^^^^^^^^^^^^^^^^^^^^^^^^^^^^^^^^^^^^^^^^^^^^^^^^
  File "/home/nate/Desktop/AutoML/engines/autogluon_wrapper.py", line 32, in __init__
    self._metric: str = DEFAULT_METRIC # Store the metric for best_pipeline_info
                        ^^^^^^^^^^^^^^
NameError: name 'DEFAULT_METRIC' is not defined

2025-06-12 14:29:54,980 - ERROR - [Orchestrator] Error from autogluon_wrapper child process:
Traceback (most recent call last):
  File "/home/nate/Desktop/AutoML/orchestrator.py", line 470, in _runner
    wrapper_instance = wrapper_class(seed=RANDOM_STATE, timeout_sec=t_sec, run_dir=r_dir)
                       ^^^^^^^^^^^^^^^^^^^^^^^^^^^^^^^^^^^^^^^^^^^^^^^^^^^^^^^^^^^^^^^^^^
  File "/home/nate/Desktop/AutoML/engines/autogluon_wrapper.py", line 32, in __init__
    self._metric: str = DEFAULT_METRIC # Store the metric for best_pipeline_info
                        ^^^^^^^^^^^^^^
NameError: name 'DEFAULT_METRIC' is not defined

2025-06-12 14:29:55,106 - ERROR - All AutoML engines failed in concurrent run.
2025-06-12 14:29:55,106 - ERROR - An error occurred during meta-search or evaluation: All AutoML engines failed in concurrent run.
Traceback (most recent call last):
  File "/home/nate/Desktop/AutoML/orchestrator.py", line 761, in _cli
    champion_model, fitted_engines, per_engine_metrics = _meta_search_concurrent(
                                                         ^^^^^^^^^^^^^^^^^^^^^^^^
  File "/home/nate/Desktop/AutoML/orchestrator.py", line 589, in _meta_search_concurrent
    raise RuntimeError("All AutoML engines failed in concurrent run.")
RuntimeError: All AutoML engines failed in concurrent run.
2025-06-12 14:31:23,301 - INFO - Data loaded successfully. X shape: (400, 38448), y shape: (400,)
2025-06-12 14:31:23,340 - INFO - Data split into training/CV (320 rows) and hold-out (80 rows) sets.
2025-06-12 14:31:24,042 - INFO - [Orchestrator|autogluon_wrapper] Child process started.
2025-06-12 14:31:24,043 - INFO - [AutoGluonEngine] search-start
2025-06-12 14:31:24,044 - ERROR - [Orchestrator|autogluon_wrapper] Engine crashed: name '_MODEL_SPACE' is not defined
Traceback (most recent call last):
  File "/home/nate/Desktop/AutoML/orchestrator.py", line 471, in _runner
    fitted_model = wrapper_instance.fit(X_obj, y_obj)
                   ^^^^^^^^^^^^^^^^^^^^^^^^^^^^^^^^^^
  File "/home/nate/Desktop/AutoML/engines/autogluon_wrapper.py", line 79, in fit
    model_families = kwargs.get("model_families", _MODEL_SPACE.keys())
                                                  ^^^^^^^^^^^^
NameError: name '_MODEL_SPACE' is not defined

2025-06-12 14:31:24,044 - ERROR - [Orchestrator] Error from autogluon_wrapper child process:
Traceback (most recent call last):
  File "/home/nate/Desktop/AutoML/orchestrator.py", line 471, in _runner
    fitted_model = wrapper_instance.fit(X_obj, y_obj)
                   ^^^^^^^^^^^^^^^^^^^^^^^^^^^^^^^^^^
  File "/home/nate/Desktop/AutoML/engines/autogluon_wrapper.py", line 79, in fit
    model_families = kwargs.get("model_families", _MODEL_SPACE.keys())
                                                  ^^^^^^^^^^^^
NameError: name '_MODEL_SPACE' is not defined

2025-06-12 14:31:24,168 - ERROR - All AutoML engines failed in concurrent run.
2025-06-12 14:31:24,169 - ERROR - An error occurred during meta-search or evaluation: All AutoML engines failed in concurrent run.
Traceback (most recent call last):
  File "/home/nate/Desktop/AutoML/orchestrator.py", line 761, in _cli
    champion_model, fitted_engines, per_engine_metrics = _meta_search_concurrent(
                                                         ^^^^^^^^^^^^^^^^^^^^^^^^
  File "/home/nate/Desktop/AutoML/orchestrator.py", line 589, in _meta_search_concurrent
    raise RuntimeError("All AutoML engines failed in concurrent run.")
RuntimeError: All AutoML engines failed in concurrent run.
2025-06-12 14:32:23,036 - INFO - Data loaded successfully. X shape: (400, 38448), y shape: (400,)
2025-06-12 14:32:23,072 - INFO - Data split into training/CV (320 rows) and hold-out (80 rows) sets.
2025-06-12 14:32:23,749 - INFO - [Orchestrator|autogluon_wrapper] Child process started.
2025-06-12 14:32:23,749 - INFO - [AutoGluonEngine] search-start
2025-06-12 14:32:24,076 - ERROR - [Orchestrator|autogluon_wrapper] Engine crashed: cannot import name 'set_seed' from 'autogluon.common.utils.utils' (/home/nate/.pyenv/versions/3.11.13/lib/python3.11/site-packages/autogluon/common/utils/utils.py)
Traceback (most recent call last):
  File "/home/nate/Desktop/AutoML/orchestrator.py", line 471, in _runner
    fitted_model = wrapper_instance.fit(X_obj, y_obj)
                   ^^^^^^^^^^^^^^^^^^^^^^^^^^^^^^^^^^
  File "/home/nate/Desktop/AutoML/engines/autogluon_wrapper.py", line 121, in fit
    from autogluon.common.utils.utils import set_seed
ImportError: cannot import name 'set_seed' from 'autogluon.common.utils.utils' (/home/nate/.pyenv/versions/3.11.13/lib/python3.11/site-packages/autogluon/common/utils/utils.py)

2025-06-12 14:32:24,077 - ERROR - [Orchestrator] Error from autogluon_wrapper child process:
Traceback (most recent call last):
  File "/home/nate/Desktop/AutoML/orchestrator.py", line 471, in _runner
    fitted_model = wrapper_instance.fit(X_obj, y_obj)
                   ^^^^^^^^^^^^^^^^^^^^^^^^^^^^^^^^^^
  File "/home/nate/Desktop/AutoML/engines/autogluon_wrapper.py", line 121, in fit
    from autogluon.common.utils.utils import set_seed
ImportError: cannot import name 'set_seed' from 'autogluon.common.utils.utils' (/home/nate/.pyenv/versions/3.11.13/lib/python3.11/site-packages/autogluon/common/utils/utils.py)

2025-06-12 14:32:24,267 - ERROR - All AutoML engines failed in concurrent run.
2025-06-12 14:32:24,267 - ERROR - An error occurred during meta-search or evaluation: All AutoML engines failed in concurrent run.
Traceback (most recent call last):
  File "/home/nate/Desktop/AutoML/orchestrator.py", line 761, in _cli
    champion_model, fitted_engines, per_engine_metrics = _meta_search_concurrent(
                                                         ^^^^^^^^^^^^^^^^^^^^^^^^
  File "/home/nate/Desktop/AutoML/orchestrator.py", line 589, in _meta_search_concurrent
    raise RuntimeError("All AutoML engines failed in concurrent run.")
RuntimeError: All AutoML engines failed in concurrent run.
2025-06-12 14:33:32,772 - INFO - Data loaded successfully. X shape: (400, 38448), y shape: (400,)
2025-06-12 14:33:32,810 - INFO - Data split into training/CV (320 rows) and hold-out (80 rows) sets.
2025-06-12 14:33:33,551 - INFO - [Orchestrator|autogluon_wrapper] Child process started.
2025-06-12 14:33:33,552 - INFO - [AutoGluonEngine] search-start
2025-06-12 14:33:33,713 - ERROR - [Orchestrator|autogluon_wrapper] Engine crashed: cannot import name 'set_seed' from 'autogluon.common.utils.utils' (/home/nate/.pyenv/versions/3.11.13/lib/python3.11/site-packages/autogluon/common/utils/utils.py)
Traceback (most recent call last):
  File "/home/nate/Desktop/AutoML/orchestrator.py", line 471, in _runner
    fitted_model = wrapper_instance.fit(X_obj, y_obj)
                   ^^^^^^^^^^^^^^^^^^^^^^^^^^^^^^^^^^
  File "/home/nate/Desktop/AutoML/engines/autogluon_wrapper.py", line 153, in fit
    from autogluon.common.utils.utils import set_seed
ImportError: cannot import name 'set_seed' from 'autogluon.common.utils.utils' (/home/nate/.pyenv/versions/3.11.13/lib/python3.11/site-packages/autogluon/common/utils/utils.py)

2025-06-12 14:33:33,714 - ERROR - [Orchestrator] Error from autogluon_wrapper child process:
Traceback (most recent call last):
  File "/home/nate/Desktop/AutoML/orchestrator.py", line 471, in _runner
    fitted_model = wrapper_instance.fit(X_obj, y_obj)
                   ^^^^^^^^^^^^^^^^^^^^^^^^^^^^^^^^^^
  File "/home/nate/Desktop/AutoML/engines/autogluon_wrapper.py", line 153, in fit
    from autogluon.common.utils.utils import set_seed
ImportError: cannot import name 'set_seed' from 'autogluon.common.utils.utils' (/home/nate/.pyenv/versions/3.11.13/lib/python3.11/site-packages/autogluon/common/utils/utils.py)

2025-06-12 14:33:33,948 - ERROR - All AutoML engines failed in concurrent run.
2025-06-12 14:33:33,948 - ERROR - An error occurred during meta-search or evaluation: All AutoML engines failed in concurrent run.
Traceback (most recent call last):
  File "/home/nate/Desktop/AutoML/orchestrator.py", line 761, in _cli
    champion_model, fitted_engines, per_engine_metrics = _meta_search_concurrent(
                                                         ^^^^^^^^^^^^^^^^^^^^^^^^
  File "/home/nate/Desktop/AutoML/orchestrator.py", line 589, in _meta_search_concurrent
    raise RuntimeError("All AutoML engines failed in concurrent run.")
RuntimeError: All AutoML engines failed in concurrent run.
2025-06-12 14:34:18,450 - INFO - Data loaded successfully. X shape: (400, 38448), y shape: (400,)
2025-06-12 14:34:18,488 - INFO - Data split into training/CV (320 rows) and hold-out (80 rows) sets.
2025-06-12 14:34:19,166 - INFO - [Orchestrator|autogluon_wrapper] Child process started.
2025-06-12 14:34:19,166 - INFO - [AutoGluonEngine] search-start
2025-06-12 14:34:19,352 - ERROR - [Orchestrator|autogluon_wrapper] Engine crashed: Invalid kwargs passed: ['random_seed']
Valid kwargs: ['learner_kwargs', 'quantile_levels', 'learner_type']
Traceback (most recent call last):
  File "/home/nate/Desktop/AutoML/orchestrator.py", line 471, in _runner
    fitted_model = wrapper_instance.fit(X_obj, y_obj)
                   ^^^^^^^^^^^^^^^^^^^^^^^^^^^^^^^^^^
  File "/home/nate/Desktop/AutoML/engines/autogluon_wrapper.py", line 165, in fit
    ag_predictor = TabularPredictor(
                   ^^^^^^^^^^^^^^^^^
  File "/home/nate/.pyenv/versions/3.11.13/lib/python3.11/site-packages/autogluon/tabular/predictor/predictor.py", line 203, in __init__
    self._validate_init_kwargs(kwargs)
  File "/home/nate/.pyenv/versions/3.11.13/lib/python3.11/site-packages/autogluon/tabular/predictor/predictor.py", line 5017, in _validate_init_kwargs
    raise ValueError(f"Invalid kwargs passed: {invalid_keys}\nValid kwargs: {list(valid_kwargs)}")
ValueError: Invalid kwargs passed: ['random_seed']
Valid kwargs: ['learner_kwargs', 'quantile_levels', 'learner_type']

2025-06-12 14:34:19,354 - ERROR - [Orchestrator] Error from autogluon_wrapper child process:
Traceback (most recent call last):
  File "/home/nate/Desktop/AutoML/orchestrator.py", line 471, in _runner
    fitted_model = wrapper_instance.fit(X_obj, y_obj)
                   ^^^^^^^^^^^^^^^^^^^^^^^^^^^^^^^^^^
  File "/home/nate/Desktop/AutoML/engines/autogluon_wrapper.py", line 165, in fit
    ag_predictor = TabularPredictor(
                   ^^^^^^^^^^^^^^^^^
  File "/home/nate/.pyenv/versions/3.11.13/lib/python3.11/site-packages/autogluon/tabular/predictor/predictor.py", line 203, in __init__
    self._validate_init_kwargs(kwargs)
  File "/home/nate/.pyenv/versions/3.11.13/lib/python3.11/site-packages/autogluon/tabular/predictor/predictor.py", line 5017, in _validate_init_kwargs
    raise ValueError(f"Invalid kwargs passed: {invalid_keys}\nValid kwargs: {list(valid_kwargs)}")
ValueError: Invalid kwargs passed: ['random_seed']
Valid kwargs: ['learner_kwargs', 'quantile_levels', 'learner_type']

2025-06-12 14:34:19,551 - ERROR - All AutoML engines failed in concurrent run.
2025-06-12 14:34:19,551 - ERROR - An error occurred during meta-search or evaluation: All AutoML engines failed in concurrent run.
Traceback (most recent call last):
  File "/home/nate/Desktop/AutoML/orchestrator.py", line 761, in _cli
    champion_model, fitted_engines, per_engine_metrics = _meta_search_concurrent(
                                                         ^^^^^^^^^^^^^^^^^^^^^^^^
  File "/home/nate/Desktop/AutoML/orchestrator.py", line 589, in _meta_search_concurrent
    raise RuntimeError("All AutoML engines failed in concurrent run.")
RuntimeError: All AutoML engines failed in concurrent run.
2025-06-12 14:34:49,063 - INFO - Data loaded successfully. X shape: (400, 38448), y shape: (400,)
2025-06-12 14:34:49,100 - INFO - Data split into training/CV (320 rows) and hold-out (80 rows) sets.
2025-06-12 14:34:49,775 - INFO - [Orchestrator|autogluon_wrapper] Child process started.
2025-06-12 14:34:49,776 - INFO - [AutoGluonEngine] search-start
2025-06-12 14:39:37,066 - INFO - Data loaded successfully. X shape: (400, 38448), y shape: (400,)
2025-06-12 14:39:37,100 - INFO - Data split into training/CV (320 rows) and hold-out (80 rows) sets.
2025-06-12 14:39:37,828 - INFO - [Orchestrator|autogluon_wrapper] Child process started.
2025-06-12 14:39:37,828 - INFO - [AutoGluonEngine] search-start
2025-06-12 14:42:29,198 - INFO - Data loaded successfully. X shape: (400, 38448), y shape: (400,)
2025-06-12 14:42:29,236 - INFO - Data split into training/CV (320 rows) and hold-out (80 rows) sets.
2025-06-12 14:42:29,932 - INFO - [Orchestrator|autogluon_wrapper] Child process started.
2025-06-12 14:42:29,932 - INFO - [AutoGluonEngine] search-start
2025-06-12 14:49:58,039 - ERROR - [Orchestrator|autogluon_wrapper] Engine crashed: Not enough time left to train models. Consider specifying a larger time_limit. Time remaining: -387.69s
Traceback (most recent call last):
  File "/home/nate/Desktop/AutoML/orchestrator.py", line 471, in _runner
    fitted_model = wrapper_instance.fit(X_obj, y_obj)
                   ^^^^^^^^^^^^^^^^^^^^^^^^^^^^^^^^^^
  File "/home/nate/Desktop/AutoML/engines/autogluon_wrapper.py", line 171, in fit
    ag_predictor.fit(
  File "/home/nate/.pyenv/versions/3.11.13/lib/python3.11/site-packages/autogluon/core/utils/decorators.py", line 31, in _call
    return f(*gargs, **gkwargs)
           ^^^^^^^^^^^^^^^^^^^^
  File "/home/nate/.pyenv/versions/3.11.13/lib/python3.11/site-packages/autogluon/tabular/predictor/predictor.py", line 1301, in fit
    self._fit(ag_fit_kwargs=ag_fit_kwargs, ag_post_fit_kwargs=ag_post_fit_kwargs)
  File "/home/nate/.pyenv/versions/3.11.13/lib/python3.11/site-packages/autogluon/tabular/predictor/predictor.py", line 1307, in _fit
    self._learner.fit(**ag_fit_kwargs)
  File "/home/nate/.pyenv/versions/3.11.13/lib/python3.11/site-packages/autogluon/tabular/learner/abstract_learner.py", line 159, in fit
    return self._fit(X=X, X_val=X_val, **kwargs)
           ^^^^^^^^^^^^^^^^^^^^^^^^^^^^^^^^^^^^^
  File "/home/nate/.pyenv/versions/3.11.13/lib/python3.11/site-packages/autogluon/tabular/learner/default_learner.py", line 133, in _fit
    trainer.fit(
  File "/home/nate/.pyenv/versions/3.11.13/lib/python3.11/site-packages/autogluon/tabular/trainer/auto_trainer.py", line 135, in fit
    self._train_multi_and_ensemble(
  File "/home/nate/.pyenv/versions/3.11.13/lib/python3.11/site-packages/autogluon/tabular/trainer/abstract_trainer.py", line 3290, in _train_multi_and_ensemble
    raise AssertionError(f"Not enough time left to train models. Consider specifying a larger time_limit. Time remaining: {round(time_limit, 2)}s")
AssertionError: Not enough time left to train models. Consider specifying a larger time_limit. Time remaining: -387.69s

2025-06-12 14:49:58,052 - ERROR - [Orchestrator] Error from autogluon_wrapper child process:
Traceback (most recent call last):
  File "/home/nate/Desktop/AutoML/orchestrator.py", line 471, in _runner
    fitted_model = wrapper_instance.fit(X_obj, y_obj)
                   ^^^^^^^^^^^^^^^^^^^^^^^^^^^^^^^^^^
  File "/home/nate/Desktop/AutoML/engines/autogluon_wrapper.py", line 171, in fit
    ag_predictor.fit(
  File "/home/nate/.pyenv/versions/3.11.13/lib/python3.11/site-packages/autogluon/core/utils/decorators.py", line 31, in _call
    return f(*gargs, **gkwargs)
           ^^^^^^^^^^^^^^^^^^^^
  File "/home/nate/.pyenv/versions/3.11.13/lib/python3.11/site-packages/autogluon/tabular/predictor/predictor.py", line 1301, in fit
    self._fit(ag_fit_kwargs=ag_fit_kwargs, ag_post_fit_kwargs=ag_post_fit_kwargs)
  File "/home/nate/.pyenv/versions/3.11.13/lib/python3.11/site-packages/autogluon/tabular/predictor/predictor.py", line 1307, in _fit
    self._learner.fit(**ag_fit_kwargs)
  File "/home/nate/.pyenv/versions/3.11.13/lib/python3.11/site-packages/autogluon/tabular/learner/abstract_learner.py", line 159, in fit
    return self._fit(X=X, X_val=X_val, **kwargs)
           ^^^^^^^^^^^^^^^^^^^^^^^^^^^^^^^^^^^^^
  File "/home/nate/.pyenv/versions/3.11.13/lib/python3.11/site-packages/autogluon/tabular/learner/default_learner.py", line 133, in _fit
    trainer.fit(
  File "/home/nate/.pyenv/versions/3.11.13/lib/python3.11/site-packages/autogluon/tabular/trainer/auto_trainer.py", line 135, in fit
    self._train_multi_and_ensemble(
  File "/home/nate/.pyenv/versions/3.11.13/lib/python3.11/site-packages/autogluon/tabular/trainer/abstract_trainer.py", line 3290, in _train_multi_and_ensemble
    raise AssertionError(f"Not enough time left to train models. Consider specifying a larger time_limit. Time remaining: {round(time_limit, 2)}s")
AssertionError: Not enough time left to train models. Consider specifying a larger time_limit. Time remaining: -387.69s

2025-06-12 14:49:58,273 - ERROR - All AutoML engines failed in concurrent run.
2025-06-12 14:49:58,273 - ERROR - An error occurred during meta-search or evaluation: All AutoML engines failed in concurrent run.
Traceback (most recent call last):
  File "/home/nate/Desktop/AutoML/orchestrator.py", line 761, in _cli
    champion_model, fitted_engines, per_engine_metrics = _meta_search_concurrent(
                                                         ^^^^^^^^^^^^^^^^^^^^^^^^
  File "/home/nate/Desktop/AutoML/orchestrator.py", line 589, in _meta_search_concurrent
    raise RuntimeError("All AutoML engines failed in concurrent run.")
RuntimeError: All AutoML engines failed in concurrent run.
2025-06-12 23:28:53,265 - ERROR - Failed to load data: Predictors file not found: DataSets/1/predictors.csv
Traceback (most recent call last):
  File "/home/nate/Desktop/AutoML/orchestrator.py", line 760, in _cli
    X, y = load_data(args.data, args.target)
           ^^^^^^^^^^^^^^^^^^^^^^^^^^^^^^^^^
  File "/home/nate/Desktop/AutoML/scripts/data_loader.py", line 55, in load_data
    raise FileNotFoundError(f"Predictors file not found: {predictors_path}")
FileNotFoundError: Predictors file not found: DataSets/1/predictors.csv
